[2024-02-25T11:07:51.901+0000] {taskinstance.py:1956} INFO - Dependencies all met for dep_context=non-requeueable deps ti=<TaskInstance: exchange_trade_data.get_exchange_data scheduled__2024-02-25T10:02:00+00:00 [queued]>
[2024-02-25T11:07:51.944+0000] {taskinstance.py:1956} INFO - Dependencies all met for dep_context=requeueable deps ti=<TaskInstance: exchange_trade_data.get_exchange_data scheduled__2024-02-25T10:02:00+00:00 [queued]>
[2024-02-25T11:07:51.945+0000] {taskinstance.py:2170} INFO - Starting attempt 1 of 1
[2024-02-25T11:07:52.018+0000] {taskinstance.py:2191} INFO - Executing <Task(_PythonDecoratedOperator): get_exchange_data> on 2024-02-25 10:02:00+00:00
[2024-02-25T11:07:52.043+0000] {standard_task_runner.py:60} INFO - Started process 2063 to run task
[2024-02-25T11:07:52.101+0000] {standard_task_runner.py:87} INFO - Running: ['***', 'tasks', 'run', 'exchange_trade_data', 'get_exchange_data', 'scheduled__2024-02-25T10:02:00+00:00', '--job-id', '30', '--raw', '--subdir', 'DAGS_FOLDER/exchange.py', '--cfg-path', '/tmp/tmp2624j0p4']
[2024-02-25T11:07:52.103+0000] {standard_task_runner.py:88} INFO - Job 30: Subtask get_exchange_data
[2024-02-25T11:07:53.497+0000] {task_command.py:423} INFO - Running <TaskInstance: exchange_trade_data.get_exchange_data scheduled__2024-02-25T10:02:00+00:00 [running]> on host f5283f9a0a92
[2024-02-25T17:12:51.298+0000] {taskinstance.py:2480} INFO - Exporting env vars: AIRFLOW_CTX_DAG_OWNER='***' AIRFLOW_CTX_DAG_ID='exchange_trade_data' AIRFLOW_CTX_TASK_ID='get_exchange_data' AIRFLOW_CTX_EXECUTION_DATE='2024-02-25T10:02:00+00:00' AIRFLOW_CTX_TRY_NUMBER='1' AIRFLOW_CTX_DAG_RUN_ID='scheduled__2024-02-25T10:02:00+00:00'
[2024-02-25T17:13:04.362+0000] {local_task_job_runner.py:211} ERROR - Heartbeat time limit exceeded!
[2024-02-25T17:13:04.364+0000] {process_utils.py:131} INFO - Sending 15 to group 2063. PIDs of all processes in the group: [2063]
[2024-02-25T17:13:04.365+0000] {process_utils.py:86} INFO - Sending the signal 15 to group 2063
[2024-02-25T17:13:04.376+0000] {taskinstance.py:2450} ERROR - Received SIGTERM. Terminating subprocesses.
[2024-02-25T17:13:04.474+0000] {taskinstance.py:2698} ERROR - Task failed with exception
Traceback (most recent call last):
  File "/home/airflow/.local/lib/python3.8/site-packages/airflow/models/taskinstance.py", line 433, in _execute_task
    result = execute_callable(context=context, **execute_callable_kwargs)
  File "/home/airflow/.local/lib/python3.8/site-packages/airflow/decorators/base.py", line 241, in execute
    return_value = super().execute(context)
  File "/home/airflow/.local/lib/python3.8/site-packages/airflow/operators/python.py", line 199, in execute
    return_value = self.execute_callable()
  File "/home/airflow/.local/lib/python3.8/site-packages/airflow/operators/python.py", line 216, in execute_callable
    return self.python_callable(*self.op_args, **self.op_kwargs)
  File "/opt/airflow/dags/exchange.py", line 34, in get_exchange_data
    response = requests.get(url)
  File "/home/airflow/.local/lib/python3.8/site-packages/requests/api.py", line 73, in get
    return request("get", url, params=params, **kwargs)
  File "/home/airflow/.local/lib/python3.8/site-packages/requests/api.py", line 59, in request
    return session.request(method=method, url=url, **kwargs)
  File "/home/airflow/.local/lib/python3.8/site-packages/requests/sessions.py", line 589, in request
    resp = self.send(prep, **send_kwargs)
  File "/home/airflow/.local/lib/python3.8/site-packages/requests/sessions.py", line 703, in send
    r = adapter.send(request, **kwargs)
  File "/home/airflow/.local/lib/python3.8/site-packages/requests/adapters.py", line 486, in send
    resp = conn.urlopen(
  File "/home/airflow/.local/lib/python3.8/site-packages/urllib3/connectionpool.py", line 715, in urlopen
    httplib_response = self._make_request(
  File "/home/airflow/.local/lib/python3.8/site-packages/urllib3/connectionpool.py", line 404, in _make_request
    self._validate_conn(conn)
  File "/home/airflow/.local/lib/python3.8/site-packages/urllib3/connectionpool.py", line 1058, in _validate_conn
    conn.connect()
  File "/home/airflow/.local/lib/python3.8/site-packages/urllib3/connection.py", line 363, in connect
    self.sock = conn = self._new_conn()
  File "/home/airflow/.local/lib/python3.8/site-packages/urllib3/connection.py", line 174, in _new_conn
    conn = connection.create_connection(
  File "/home/airflow/.local/lib/python3.8/site-packages/urllib3/util/connection.py", line 85, in create_connection
    sock.connect(sa)
  File "/home/airflow/.local/lib/python3.8/site-packages/airflow/models/taskinstance.py", line 2452, in signal_handler
    raise AirflowException("Task received SIGTERM signal")
airflow.exceptions.AirflowException: Task received SIGTERM signal
[2024-02-25T17:13:05.176+0000] {taskinstance.py:1138} INFO - Marking task as FAILED. dag_id=exchange_trade_data, task_id=get_exchange_data, execution_date=20240225T100200, start_date=20240225T110751, end_date=20240225T171305
[2024-02-25T17:13:05.400+0000] {standard_task_runner.py:107} ERROR - Failed to execute job 30 for task get_exchange_data (Task received SIGTERM signal; 2063)
[2024-02-25T17:13:05.729+0000] {process_utils.py:79} INFO - Process psutil.Process(pid=2063, status='terminated', exitcode=1, started='11:07:51') (2063) terminated with exit code 1
