[2024-02-26T07:32:06.041+0000] {taskinstance.py:1956} INFO - Dependencies all met for dep_context=non-requeueable deps ti=<TaskInstance: exchange_trade_data.transform_exchange_data manual__2024-02-26T07:31:58.452596+00:00 [queued]>
[2024-02-26T07:32:06.059+0000] {taskinstance.py:1956} INFO - Dependencies all met for dep_context=requeueable deps ti=<TaskInstance: exchange_trade_data.transform_exchange_data manual__2024-02-26T07:31:58.452596+00:00 [queued]>
[2024-02-26T07:32:06.060+0000] {taskinstance.py:2170} INFO - Starting attempt 1 of 1
[2024-02-26T07:32:06.278+0000] {taskinstance.py:2191} INFO - Executing <Task(_PythonDecoratedOperator): transform_exchange_data> on 2024-02-26 07:31:58.452596+00:00
[2024-02-26T07:32:06.287+0000] {standard_task_runner.py:60} INFO - Started process 3055 to run task
[2024-02-26T07:32:06.292+0000] {standard_task_runner.py:87} INFO - Running: ['***', 'tasks', 'run', 'exchange_trade_data', 'transform_exchange_data', 'manual__2024-02-26T07:31:58.452596+00:00', '--job-id', '49', '--raw', '--subdir', 'DAGS_FOLDER/exchange.py', '--cfg-path', '/tmp/tmpmy7d9u3b']
[2024-02-26T07:32:06.294+0000] {standard_task_runner.py:88} INFO - Job 49: Subtask transform_exchange_data
[2024-02-26T07:32:06.359+0000] {task_command.py:423} INFO - Running <TaskInstance: exchange_trade_data.transform_exchange_data manual__2024-02-26T07:31:58.452596+00:00 [running]> on host f5283f9a0a92
[2024-02-26T07:32:06.499+0000] {taskinstance.py:2480} INFO - Exporting env vars: AIRFLOW_CTX_DAG_OWNER='***' AIRFLOW_CTX_DAG_ID='exchange_trade_data' AIRFLOW_CTX_TASK_ID='transform_exchange_data' AIRFLOW_CTX_EXECUTION_DATE='2024-02-26T07:31:58.452596+00:00' AIRFLOW_CTX_TRY_NUMBER='1' AIRFLOW_CTX_DAG_RUN_ID='manual__2024-02-26T07:31:58.452596+00:00'
[2024-02-26T07:32:06.502+0000] {taskinstance.py:2698} ERROR - Task failed with exception
Traceback (most recent call last):
  File "/home/airflow/.local/lib/python3.8/site-packages/airflow/models/taskinstance.py", line 433, in _execute_task
    result = execute_callable(context=context, **execute_callable_kwargs)
  File "/home/airflow/.local/lib/python3.8/site-packages/airflow/decorators/base.py", line 241, in execute
    return_value = super().execute(context)
  File "/home/airflow/.local/lib/python3.8/site-packages/airflow/operators/python.py", line 199, in execute
    return_value = self.execute_callable()
  File "/home/airflow/.local/lib/python3.8/site-packages/airflow/operators/python.py", line 216, in execute_callable
    return self.python_callable(*self.op_args, **self.op_kwargs)
  File "/opt/airflow/dags/exchange.py", line 61, in transform_exchange_data
    'updated_at': get_utc_from_unix_time(result.get('updated')).output().apply(lambda x: x.isoformat() if x else None)
AttributeError: 'PlainXComArg' object has no attribute 'output'
[2024-02-26T07:32:06.513+0000] {taskinstance.py:1138} INFO - Marking task as FAILED. dag_id=exchange_trade_data, task_id=transform_exchange_data, execution_date=20240226T073158, start_date=20240226T073206, end_date=20240226T073206
[2024-02-26T07:32:06.536+0000] {standard_task_runner.py:107} ERROR - Failed to execute job 49 for task transform_exchange_data ('PlainXComArg' object has no attribute 'output'; 3055)
[2024-02-26T07:32:06.586+0000] {local_task_job_runner.py:234} INFO - Task exited with return code 1
[2024-02-26T07:32:06.628+0000] {taskinstance.py:3280} INFO - 0 downstream tasks scheduled from follow-on schedule check
